Exception in thread Thread-3:
Traceback (most recent call last):
  File "/net/data.isilon/ag-saez/bq_efewings/tools/miniconda3/envs/scRNA_p3/lib/python3.8/threading.py", line 932, in _bootstrap_inner
    self.run()
  File "/net/data.isilon/ag-saez/bq_efewings/tools/miniconda3/envs/scRNA_p3/lib/python3.8/threading.py", line 870, in run
    self._target(*self._args, **self._kwargs)
  File "/net/data.isilon/ag-saez/bq_efewings/tools/miniconda3/envs/scRNA_p3/lib/python3.8/site-packages/multiprocess/pool.py", line 592, in _handle_results
    cache[job]._set(i, obj)
  File "/net/data.isilon/ag-saez/bq_efewings/tools/miniconda3/envs/scRNA_p3/lib/python3.8/site-packages/multiprocess/pool.py", line 778, in _set
    self._error_callback(self._value)
TypeError: '_io.TextIOWrapper' object is not callable
